在这段代码中，我们展示了 Python 中的异常处理机制，包括 `try`、`except`、`finally` 和 `raise` 语句。下面是对代码的详细解释：

### 异常处理示例

```python
try:
    meaning = 42
    print(meaning / 0)
    print("the meaning of life")
except (ValueError, TypeError):
    print("ValueError or TypeError occurred")
except ZeroDivisionError:
    print("Divided by zero")  # 最终输出是这个
```

在这段代码中，我们尝试执行一些可能会引发异常的代码。`try` 块中的代码会尝试执行，如果发生异常，则会根据异常类型执行相应的 `except` 块。

- `meaning / 0`：这行代码会引发 `ZeroDivisionError` 异常。
- `except (ValueError, TypeError)`：捕获 `ValueError` 或 `TypeError` 异常，并打印相应的消息。
- `except ZeroDivisionError`：捕获 `ZeroDivisionError` 异常，并打印相应的消息。

由于 `meaning / 0` 引发了 `ZeroDivisionError` 异常，所以最终输出是 `Divided by zero`。

### 使用 `finally` 块

```python
try:
    print("hello ")
except:
    print("dddddd")
finally:
    print("world")  # 最终输出是 hello \n world
```

在这段代码中，我们展示了 `finally` 块的使用。`finally` 块中的代码无论 `try` 块中是否发生异常都会执行。

- `try` 块中的代码 `print("hello ")` 会正常执行，不会引发异常。
- `finally` 块中的代码 `print("world")` 会在 `try` 块执行完毕后执行。

最终输出是 `hello \n world`。

### 使用 `raise` 语句

```python
# print(1)
# raise ValueError  # 输出是 1 和 ValueError
# print(2)
```

在这段代码中，我们展示了如何使用 `raise` 语句手动引发异常。

- `print(1)`：这行代码会正常执行，输出 `1`。
- `raise ValueError`：这行代码会手动引发 `ValueError` 异常。
- `print(2)`：这行代码不会执行，因为在它之前已经引发了异常。

最终输出是 `1` 和 `ValueError`。

### 在 `except` 块中引发异常

```python
# try:
#     print(1 / 0)
# except ZeroDivisionError:
#     raise ValueError  # 错误是 ZeroDivisionError 和 ValueError
```

在这段代码中，我们展示了如何在 `except` 块中引发新的异常。

- `print(1 / 0)`：这行代码会引发 `ZeroDivisionError` 异常。
- `except ZeroDivisionError`：捕获 `ZeroDivisionError` 异常。
- `raise ValueError`：在 `except` 块中引发新的 `ValueError` 异常。

最终错误是 `ZeroDivisionError` 和 `ValueError`。

### 使用 `raise` 语句引发自定义异常

```python
# name = "123"
# raise NameError("Invalid name!")  # 最终输出可以被参数影响
```

在这段代码中，我们展示了如何使用 `raise` 语句引发自定义异常。

- `name = "123"`：这行代码会正常执行。
- `raise NameError("Invalid name!")`：这行代码会手动引发 `NameError` 异常，并附带自定义的错误消息。

最终输出是 `NameError: Invalid name!`。

### 知识点总结

1. **`try` 块**：尝试执行一些可能会引发异常的代码。
2. **`except` 块**：捕获并处理特定类型的异常。
3. **`finally` 块**：无论 `try` 块中是否发生异常，都会执行的代码块。
4. **`raise` 语句**：手动引发异常，可以是内置异常类型，也可以是自定义异常。

希望这些解释对你理解 Python 中的异常处理机制有所帮助！
<!--stackedit_data:
eyJoaXN0b3J5IjpbMzMyMjg3MDUxXX0=
-->